[2022-06-22 01:18:56,881] {taskinstance.py:1159} INFO - Dependencies all met for <TaskInstance: my_dag.inference manual__2022-06-21T23:18:54.018767+00:00 [queued]>
[2022-06-22 01:18:56,883] {taskinstance.py:1159} INFO - Dependencies all met for <TaskInstance: my_dag.inference manual__2022-06-21T23:18:54.018767+00:00 [queued]>
[2022-06-22 01:18:56,883] {taskinstance.py:1356} INFO - 
--------------------------------------------------------------------------------
[2022-06-22 01:18:56,883] {taskinstance.py:1357} INFO - Starting attempt 1 of 1
[2022-06-22 01:18:56,883] {taskinstance.py:1358} INFO - 
--------------------------------------------------------------------------------
[2022-06-22 01:18:56,900] {taskinstance.py:1377} INFO - Executing <Task(PythonOperator): inference> on 2022-06-21 23:18:54.018767+00:00
[2022-06-22 01:18:56,902] {standard_task_runner.py:52} INFO - Started process 5728 to run task
[2022-06-22 01:18:56,904] {standard_task_runner.py:79} INFO - Running: ['airflow', 'tasks', 'run', 'my_dag', 'inference', 'manual__2022-06-21T23:18:54.018767+00:00', '--job-id', '16', '--raw', '--subdir', 'DAGS_FOLDER/CarPriceDag.py', '--cfg-path', '/tmp/tmpo3lrzgjc', '--error-file', '/tmp/tmpiy1jehrn']
[2022-06-22 01:18:56,904] {standard_task_runner.py:80} INFO - Job 16: Subtask inference
[2022-06-22 01:18:56,938] {task_command.py:369} INFO - Running <TaskInstance: my_dag.inference manual__2022-06-21T23:18:54.018767+00:00 [running]> on host DESKTOP-9B44JSS.localdomain
[2022-06-22 01:18:56,992] {taskinstance.py:1569} INFO - Exporting the following env vars:
AIRFLOW_CTX_DAG_OWNER=airflow
AIRFLOW_CTX_DAG_ID=my_dag
AIRFLOW_CTX_TASK_ID=inference
AIRFLOW_CTX_EXECUTION_DATE=2022-06-21T23:18:54.018767+00:00
AIRFLOW_CTX_TRY_NUMBER=1
AIRFLOW_CTX_DAG_RUN_ID=manual__2022-06-21T23:18:54.018767+00:00
[2022-06-22 01:18:56,993] {taskinstance.py:1889} ERROR - Task failed with exception
Traceback (most recent call last):
  File "/root/airflow_env/lib/python3.8/site-packages/airflow/operators/python.py", line 171, in execute
    return_value = self.execute_callable()
  File "/root/airflow_env/lib/python3.8/site-packages/airflow/operators/python.py", line 189, in execute_callable
    return self.python_callable(*self.op_args, **self.op_kwargs)
  File "/root/airflow/dags/CarPriceDag.py", line 23, in fetchdata
    bulk=pd.read_csv(r"//wsl.localhost//Ubuntu-20.04//root//airflow//dags//true_car_listings.csv")
  File "/root/airflow_env/lib/python3.8/site-packages/pandas/util/_decorators.py", line 311, in wrapper
    return func(*args, **kwargs)
  File "/root/airflow_env/lib/python3.8/site-packages/pandas/io/parsers/readers.py", line 680, in read_csv
    return _read(filepath_or_buffer, kwds)
  File "/root/airflow_env/lib/python3.8/site-packages/pandas/io/parsers/readers.py", line 575, in _read
    parser = TextFileReader(filepath_or_buffer, **kwds)
  File "/root/airflow_env/lib/python3.8/site-packages/pandas/io/parsers/readers.py", line 933, in __init__
    self._engine = self._make_engine(f, self.engine)
  File "/root/airflow_env/lib/python3.8/site-packages/pandas/io/parsers/readers.py", line 1217, in _make_engine
    self.handles = get_handle(  # type: ignore[call-overload]
  File "/root/airflow_env/lib/python3.8/site-packages/pandas/io/common.py", line 789, in get_handle
    handle = open(
FileNotFoundError: [Errno 2] No such file or directory: '//wsl.localhost//Ubuntu-20.04//root//airflow//dags//true_car_listings.csv'
[2022-06-22 01:18:56,995] {taskinstance.py:1395} INFO - Marking task as FAILED. dag_id=my_dag, task_id=inference, execution_date=20220621T231854, start_date=20220621T231856, end_date=20220621T231856
[2022-06-22 01:18:57,014] {standard_task_runner.py:92} ERROR - Failed to execute job 16 for task inference ([Errno 2] No such file or directory: '//wsl.localhost//Ubuntu-20.04//root//airflow//dags//true_car_listings.csv'; 5728)
[2022-06-22 01:18:57,037] {local_task_job.py:156} INFO - Task exited with return code 1
[2022-06-22 01:18:57,052] {local_task_job.py:273} INFO - 0 downstream tasks scheduled from follow-on schedule check
