[2022-06-22 02:00:01,961] {taskinstance.py:1159} INFO - Dependencies all met for <TaskInstance: my_dag.inference scheduled__2022-06-21T00:00:00+00:00 [queued]>
[2022-06-22 02:00:01,963] {taskinstance.py:1159} INFO - Dependencies all met for <TaskInstance: my_dag.inference scheduled__2022-06-21T00:00:00+00:00 [queued]>
[2022-06-22 02:00:01,963] {taskinstance.py:1356} INFO - 
--------------------------------------------------------------------------------
[2022-06-22 02:00:01,964] {taskinstance.py:1357} INFO - Starting attempt 1 of 1
[2022-06-22 02:00:01,964] {taskinstance.py:1358} INFO - 
--------------------------------------------------------------------------------
[2022-06-22 02:00:01,980] {taskinstance.py:1377} INFO - Executing <Task(PythonOperator): inference> on 2022-06-21 00:00:00+00:00
[2022-06-22 02:00:01,982] {standard_task_runner.py:52} INFO - Started process 9426 to run task
[2022-06-22 02:00:01,984] {standard_task_runner.py:79} INFO - Running: ['airflow', 'tasks', 'run', 'my_dag', 'inference', 'scheduled__2022-06-21T00:00:00+00:00', '--job-id', '26', '--raw', '--subdir', 'DAGS_FOLDER/CarPriceDag.py', '--cfg-path', '/tmp/tmphom8jh35', '--error-file', '/tmp/tmp5y7gwv9s']
[2022-06-22 02:00:01,985] {standard_task_runner.py:80} INFO - Job 26: Subtask inference
[2022-06-22 02:00:02,016] {task_command.py:369} INFO - Running <TaskInstance: my_dag.inference scheduled__2022-06-21T00:00:00+00:00 [running]> on host DESKTOP-9B44JSS.localdomain
[2022-06-22 02:00:02,063] {taskinstance.py:1569} INFO - Exporting the following env vars:
AIRFLOW_CTX_DAG_OWNER=airflow
AIRFLOW_CTX_DAG_ID=my_dag
AIRFLOW_CTX_TASK_ID=inference
AIRFLOW_CTX_EXECUTION_DATE=2022-06-21T00:00:00+00:00
AIRFLOW_CTX_TRY_NUMBER=1
AIRFLOW_CTX_DAG_RUN_ID=scheduled__2022-06-21T00:00:00+00:00
[2022-06-22 02:00:03,750] {taskinstance.py:1889} ERROR - Task failed with exception
Traceback (most recent call last):
  File "/root/airflow_env/lib/python3.8/site-packages/requests/models.py", line 910, in json
    return complexjson.loads(self.text, **kwargs)
  File "/usr/lib/python3.8/json/__init__.py", line 357, in loads
    return _default_decoder.decode(s)
  File "/usr/lib/python3.8/json/decoder.py", line 337, in decode
    obj, end = self.raw_decode(s, idx=_w(s, 0).end())
  File "/usr/lib/python3.8/json/decoder.py", line 355, in raw_decode
    raise JSONDecodeError("Expecting value", s, err.value) from None
json.decoder.JSONDecodeError: Expecting value: line 1 column 1 (char 0)

During handling of the above exception, another exception occurred:

Traceback (most recent call last):
  File "/root/airflow_env/lib/python3.8/site-packages/airflow/operators/python.py", line 171, in execute
    return_value = self.execute_callable()
  File "/root/airflow_env/lib/python3.8/site-packages/airflow/operators/python.py", line 189, in execute_callable
    return self.python_callable(*self.op_args, **self.op_kwargs)
  File "/root/airflow/dags/CarPriceDag.py", line 27, in fetchdata
    process(dfjson, 'https://dora-carprice-fapi.herokuapp.com/prediction/')
  File "/root/airflow/dags/CarPriceDag.py", line 18, in process
    print(r.json())
  File "/root/airflow_env/lib/python3.8/site-packages/requests/models.py", line 917, in json
    raise RequestsJSONDecodeError(e.msg, e.doc, e.pos)
requests.exceptions.JSONDecodeError: [Errno Expecting value] Internal Server Error: 0
[2022-06-22 02:00:03,753] {taskinstance.py:1395} INFO - Marking task as FAILED. dag_id=my_dag, task_id=inference, execution_date=20220621T000000, start_date=20220622T000001, end_date=20220622T000003
[2022-06-22 02:00:03,768] {standard_task_runner.py:92} ERROR - Failed to execute job 26 for task inference ([Errno Expecting value] Internal Server Error: 0; 9426)
[2022-06-22 02:00:03,806] {local_task_job.py:156} INFO - Task exited with return code 1
[2022-06-22 02:00:03,815] {local_task_job.py:273} INFO - 0 downstream tasks scheduled from follow-on schedule check
